{
    "registryname": "endless_furnace",
    "localizedname": "\u65e0\u5c3d\u7089",
	"requires-blueprint": false,
	"color": "f0f0ff",
	"modifiers": [
        {
            "elements": "avaritia:block_resource@0",
            "x": 0,
            "y": 2,
            "z": 0,
            "description": "\u7528\u4e2d\u5b50\u7d20\u5757\u66ff\u6362\u63a7\u5236\u5668\u4e0a\u65b9\u7684\u5f3a\u5316\u673a\u68b0\u5916\u58f3\n\u5df2\u83b7\u5f97\u53cc\u500d\u7684\u4ea7\u51fa\uff01\n\u5982\u679c\u662f\u65e0\u5c3d\u5757\uff0c\u5219\u4ea7\u51fa\u63d0\u5347\u81f3\u4e09\u500d\uff01",
            "modifier": {
                "target": "modularmachinery:item",
                "io": "output",
                "operation": 1,
                "multiplier": 2.0
            }
        },
		{
            "elements": "avaritia:block_resource@1",
            "x": 0,
            "y": 2,
            "z": 0,
            "modifier": {
                "target": "modularmachinery:item",
                "io": "output",
                "operation": 1,
                "multiplier": 3.0
            }
        }
		
    ],
    "parts": [
        {
            "x": -1,
            "y": 0,
            "z": 0,
            "elements": "modularmachinery:blockcasing@5"
        },
        {
            "x": -1,
            "y": 0,
            "z": 1,
            "elements": "thermalfoundation:storage@8"
        },
        {
            "x": 0,
            "y": 2,
            "z": 2,
            "elements": "modularmachinery:blockcasing@4"
        },
        {
            "x": 1,
            "y": 2,
            "z": 1,
            "elements": [
                "modularmachinery:blockinputbus",
				"modularmachinery:blockfluidinputhatch"
            ]
        },
        {
            "x": 0,
            "y": 0,
            "z": 1,
            "elements": "nuclearcraft:cooler@10"
        },
        {
            "x": 1,
            "y": 0,
            "z": 0,
            "elements": "modularmachinery:blockcasing@5"
        },
        {
            "x": -1,
            "y": 0,
            "z": 2,
            "elements": "draconicevolution:draconic_block@0"
        },
        {
            "x": 1,
            "y": 2,
            "z": 2,
            "elements": [
                "modularmachinery:blockfluidinputhatch",
				"modularmachinery:blockinputbus"
            ]
        },
        {
            "x": 1,
            "y": 0,
            "z": 1,
            "elements": "thermalfoundation:storage@8"
        },
        {
            "x": 0,
            "y": 0,
            "z": 2,
            "elements": "deepmoblearning:infused_ingot_block@0"
        },
        {
            "x": 1,
            "y": 0,
            "z": 2,
            "elements": "draconicevolution:draconic_block@0"
        },
        {
            "x": -1,
            "y": 3,
            "z": 0,
            "elements": "twilightforest:castle_stairs@2"
        },
        {
            "x": 0,
            "y": 3,
            "z": 0,
            "elements": "twilightforest:castle_stairs@2"
        },
        {
            "x": 1,
            "y": -1,
            "z": 0,
            "elements": "modularmachinery:blockcasing@4"
        },
        {
            "x": -1,
            "y": 3,
            "z": 1,
            "elements": "twilightforest:castle_stairs@0"
        },
        {
            "x": 0,
            "y": 3,
            "z": 1,
            "elements": "immersiveengineering:metal_decoration0@2"
        },
        {
            "x": 1,
            "y": 3,
            "z": 0,
            "elements": "twilightforest:castle_stairs@2"
        },
        {
            "x": 0,
            "y": -1,
            "z": 0,
            "elements": "modularmachinery:blockcasing@4"
        },
        {
            "x": -1,
            "y": 1,
            "z": 0,
            "elements": "enderio:block_alloy_endergy@3"
        },
        {
            "x": -1,
            "y": 3,
            "z": 2,
            "elements": "twilightforest:castle_stairs@3"
        },
        {
            "x": 0,
            "y": 3,
            "z": 2,
            "elements": "twilightforest:castle_stairs@3"
        },
        {
            "x": 1,
            "y": 3,
            "z": 1,
            "elements": "twilightforest:castle_stairs@1"
        },
        {
            "x": -1,
            "y": -1,
            "z": 0,
            "elements": "modularmachinery:blockcasing@4"
        },
        {
            "x": 0,
            "y": 1,
            "z": 0,
            "elements": "twilightforest:castle_rune_brick@1"
        },
        {
            "x": -1,
            "y": 1,
            "z": 1,
            "elements": "avaritia:block_resource@2"
        },
        {
            "x": 1,
            "y": 3,
            "z": 2,
            "elements": "twilightforest:castle_stairs@3"
        },
        {
            "x": 0,
            "y": 1,
            "z": 1,
            "elements": "ic2:uu_matter@0"
        },
        {
            "x": 1,
            "y": 1,
            "z": 0,
            "elements": "enderio:block_alloy_endergy@3"
        },
        {
            "x": -1,
            "y": 1,
            "z": 2,
            "elements": "enderio:block_alloy_endergy@3"
        },
        {
            "x": 0,
            "y": 1,
            "z": 2,
            "elements": "twilightforest:castle_rune_brick@1"
        },
        {
            "x": 1,
            "y": 1,
            "z": 1,
            "elements": "avaritia:block_resource@2"
        },
        {
            "x": -1,
            "y": -1,
            "z": 1,
            "elements": "modularmachinery:blockcasing@4"
        },
        {
            "x": 1,
            "y": 1,
            "z": 2,
            "elements": "enderio:block_alloy_endergy@3"
        },
        {
            "x": 0,
            "y": -1,
            "z": 1,
            "elements": "modularmachinery:blockcasing@4"
        },
        {
            "x": -1,
            "y": -1,
            "z": 2,
            "elements": "modularmachinery:blockcasing@4"
        },
        {
            "x": 0,
            "y": -1,
            "z": 2,
            "elements": "modularmachinery:blockcasing@4"
        },
        {
            "x": 1,
            "y": -1,
            "z": 1,
            "elements": "modularmachinery:blockcasing@4"
        },
        {
            "x": 1,
            "y": -1,
            "z": 2,
            "elements": "modularmachinery:blockcasing@4"
        },
        {
            "x": -1,
            "y": 2,
            "z": 0,
            "elements": [
                "modularmachinery:blockfluidoutputhatch",
				"modularmachinery:blockoutputbus"
            ]
        },
        {
            "x": 0,
            "y": 4,
            "z": 1,
            "elements": [
                "modularmachinery:blockenergyinputhatch"
            ]
        },
        {
            "x": -1,
            "y": 2,
            "z": 1,
            "elements": [
                "modularmachinery:blockoutputbus",
				"modularmachinery:blockfluidoutputhatch"
            ]
        },
        {
            "x": 0,
            "y": 2,
            "z": 0,
            "elements": "modularmachinery:blockcasing@4"
        },
        {
            "x": -1,
            "y": 2,
            "z": 2,
            "elements": [
                "modularmachinery:blockfluidoutputhatch",
				"modularmachinery:blockoutputbus"
            ]
        },
        {
            "x": 0,
            "y": 2,
            "z": 1,
            "elements": "modularmachinery:blockcasing@4"
        },
        {
            "x": 1,
            "y": 2,
            "z": 0,
            "elements": [
                "modularmachinery:blockfluidinputhatch",
				"modularmachinery:blockinputbus"
            ]
        }
    ]
}