{
    "registryname": "mechanical_assembly_plant",
    "localizedname": "\u673a\u68b0\u88c5\u914d\u5382",
	"requires-blueprint": false,
	"color": "4a4a4a",
    "parts": [
        {
            "x": -1,
            "y": 0,
            "z": 0,
            "elements": "modularmachinery:blockcasing@5"
        },
        {
            "x": 1,
            "y": 2,
            "z": 1,
            "elements": "immersiveengineering:storage@8"
        },
        {
            "x": 2,
            "y": 2,
            "z": 1,
            "elements": "appliedenergistics2:quartz_vibrant_glass@0"
        },
        {
            "x": 1,
            "y": 0,
            "z": 0,
            "elements": "appliedenergistics2:smooth_sky_stone_block@0"
        },
        {
            "x": -1,
            "y": 0,
            "z": 2,
            "elements": "modularmachinery:blockcasing@0"
        },
        {
            "x": 3,
            "y": 2,
            "z": 1,
            "elements": "appliedenergistics2:quartz_vibrant_glass@0"
        },
        {
            "x": 0,
            "y": 0,
            "z": 2,
            "elements": "immersiveengineering:storage@8"
        },
		{
            "x": 1,
            "y": 0,
            "z": 2,
            "elements": "immersiveengineering:storage@8"
        },
		{
            "x": 1,
            "y": 0,
            "z": 1,
            "elements": "immersiveengineering:storage@8"
        },
        {
            "x": 2,
            "y": 0,
            "z": 0,
            "elements": "appliedenergistics2:quartz_vibrant_glass@0"
        },
        {
            "x": 1,
            "y": 2,
            "z": 3,
            "elements": "appliedenergistics2:smooth_sky_stone_block@0"
        },
        {
            "x": 2,
            "y": 2,
            "z": 3,
            "elements": "immersiveengineering:storage@8"
        },
        {
            "x": 4,
            "y": 2,
            "z": 1,
            "elements": "immersiveengineering:storage@8"
        },
        {
            "x": 3,
            "y": 0,
            "z": 0,
            "elements": "appliedenergistics2:quartz_vibrant_glass@0"
        },
        {
            "x": 2,
            "y": 0,
            "z": 2,
            "elements": "minecraft:lava@0"
        },
        {
            "x": 4,
            "y": 0,
            "z": 0,
            "elements": "appliedenergistics2:smooth_sky_stone_block@0"
        },
        {
            "x": 3,
            "y": 2,
            "z": 3,
            "elements": "immersiveengineering:storage@8"
        },
        {
            "x": 4,
            "y": 2,
            "z": 3,
            "elements": "appliedenergistics2:smooth_sky_stone_block@0"
        },
        {
            "x": 3,
            "y": 0,
            "z": 2,
            "elements": "minecraft:lava@0"
        },
        {
            "x": 4,
            "y": 0,
            "z": 2,
            "elements":  [
			"modularmachinery:blockenergyinputhatch"
			]
        },
        {
            "x": 4,
            "y": -1,
            "z": 0,
            "elements": "modularmachinery:blockcasing@4"
        },
        {
            "x": 3,
            "y": -1,
            "z": 0,
            "elements": "modularmachinery:blockcasing@4"
        },
        {
            "x": 2,
            "y": -1,
            "z": 0,
            "elements": "modularmachinery:blockcasing@4"
        },
        {
            "x": 1,
            "y": -1,
            "z": 0,
            "elements": "modularmachinery:blockcasing@4"
        },
        {
            "x": 0,
            "y": -1,
            "z": 0,
            "elements": "modularmachinery:blockcasing@4"
        },
        {
            "x": -1,
            "y": 1,
            "z": 0,
            "elements": "immersiveengineering:storage_slab@5"
        },
        {
            "x": 0,
            "y": 1,
            "z": 0,
            "elements": "immersiveengineering:storage_slab@5"
        },
        {
            "x": -1,
            "y": -1,
            "z": 0,
            "elements": "modularmachinery:blockcasing@4"
        },
        {
            "x": -1,
            "y": 1,
            "z": 2,
            "elements": "immersiveengineering:storage_slab@5"
        },
        {
            "x": 1,
            "y": 1,
            "z": 0,
            "elements": "appliedenergistics2:smooth_sky_stone_block@0"
        },
        {
            "x": 0,
            "y": 1,
            "z": 2,
            "elements": "immersiveengineering:storage_slab@5"
        },
        {
            "x": 2,
            "y": 1,
            "z": 0,
            "elements": "appliedenergistics2:quartz_vibrant_glass@0"
        },
        {
            "x": -1,
            "y": -1,
            "z": 1,
            "elements": "modularmachinery:blockcasing@4"
        },
        {
            "x": 0,
            "y": -1,
            "z": 1,
            "elements": "modularmachinery:blockcasing@0"
        },
        {
            "x": 1,
            "y": 1,
            "z": 2,
            "elements": "modularmachinery:blockcasing@3"
        },
        {
            "x": 3,
            "y": 1,
            "z": 0,
            "elements": "appliedenergistics2:quartz_vibrant_glass@0"
        },
        {
            "x": 2,
            "y": 1,
            "z": 2,
            "elements": "minecraft:lava@0"
        },
        {
            "x": 1,
            "y": -1,
            "z": 1,
            "elements": "modularmachinery:blockcasing@0"
        },
        {
            "x": 4,
            "y": 1,
            "z": 0,
            "elements": "appliedenergistics2:smooth_sky_stone_block@0"
        },
        {
            "x": -1,
            "y": -1,
            "z": 3,
            "elements": "modularmachinery:blockcasing@4"
        },
        {
            "x": 0,
            "y": -1,
            "z": 3,
            "elements": "modularmachinery:blockcasing@4"
        },
        {
            "x": 3,
            "y": 1,
            "z": 2,
            "elements": "minecraft:lava@0"
        },
        {
            "x": 2,
            "y": -1,
            "z": 1,
            "elements": "modularmachinery:blockcasing@0"
        },
        {
            "x": 1,
            "y": -1,
            "z": 3,
            "elements": "modularmachinery:blockcasing@4"
        },
        {
            "x": 4,
            "y": 1,
            "z": 2,
            "elements": "modularmachinery:blockcasing@3"
        },
        {
            "x": 3,
            "y": -1,
            "z": 1,
            "elements": "modularmachinery:blockcasing@0"
        },
        {
            "x": 2,
            "y": -1,
            "z": 3,
            "elements": "modularmachinery:blockcasing@4"
        },
        {
            "x": 4,
            "y": -1,
            "z": 1,
            "elements": "modularmachinery:blockcasing@4"
        },
        {
            "x": 3,
            "y": -1,
            "z": 3,
            "elements": "modularmachinery:blockcasing@4"
        },
        {
            "x": 4,
            "y": -1,
            "z": 3,
            "elements": "modularmachinery:blockcasing@4"
        },
        {
            "x": 1,
            "y": 2,
            "z": 0,
            "elements": "appliedenergistics2:smooth_sky_stone_block@0"
        },
        {
            "x": 2,
            "y": 2,
            "z": 0,
            "elements": "appliedenergistics2:quartz_vibrant_glass@0"
        },
        {
            "x": -1,
            "y": 0,
            "z": 1,
            "elements": [
                "modularmachinery:blockoutputbus"
            ]
        },
        {
            "x": 0,
            "y": 0,
            "z": 1,
            "elements": "immersiveengineering:storage@8"
        },
        {
            "x": 3,
            "y": 2,
            "z": 0,
            "elements": "appliedenergistics2:quartz_vibrant_glass@0"
        },
        {
            "x": 1,
            "y": 2,
            "z": 2,
            "elements": "immersiveengineering:storage@8"
        },
        {
            "x": 2,
            "y": 2,
            "z": 2,
            "elements": "appliedenergistics2:quartz_vibrant_glass@0"
        },
        {
            "x": 4,
            "y": 2,
            "z": 0,
            "elements": "appliedenergistics2:smooth_sky_stone_block@0"
        },
        {
            "x": -1,
            "y": 0,
            "z": 3,
            "elements": "modularmachinery:blockcasing@0"
        },
        {
            "x": 2,
            "y": 0,
            "z": 1,
            "elements": "minecraft:lava@0"
        },
        {
            "x": 0,
            "y": 0,
            "z": 3,
            "elements": "modularmachinery:blockcasing@0"
        },
        {
            "x": 3,
            "y": 2,
            "z": 2,
            "elements": "appliedenergistics2:quartz_vibrant_glass@0"
        },
        {
            "x": 1,
            "y": 0,
            "z": 3,
            "elements": "appliedenergistics2:smooth_sky_stone_block@0"
        },
        {
            "x": 4,
            "y": 2,
            "z": 2,
            "elements": "immersiveengineering:storage@8"
        },
        {
            "x": 3,
            "y": 0,
            "z": 1,
            "elements": "minecraft:lava@0"
        },
        {
            "x": 4,
            "y": 0,
            "z": 1,
            "elements": [
                "modularmachinery:blockinputbus"
            ]
        },
        {
            "x": 2,
            "y": 0,
            "z": 3,
            "elements": "immersiveengineering:storage@8"
        },
        {
            "x": 3,
            "y": 0,
            "z": 3,
            "elements": "immersiveengineering:storage@8"
        },
        {
            "x": 4,
            "y": 0,
            "z": 3,
            "elements": "appliedenergistics2:smooth_sky_stone_block@0"
        },
        {
            "x": -1,
            "y": 1,
            "z": 1,
            "elements": "immersiveengineering:storage_slab@5"
        },
        {
            "x": 0,
            "y": 1,
            "z": 1,
            "elements": "immersiveengineering:storage_slab@5"
        },
        {
            "x": -1,
            "y": 1,
            "z": 3,
            "elements": "immersiveengineering:storage_slab@5"
        },
        {
            "x": 1,
            "y": 1,
            "z": 1,
            "elements": "modularmachinery:blockcasing@3"
        },
        {
            "x": 0,
            "y": 1,
            "z": 3,
            "elements": "immersiveengineering:storage_slab@5"
        },
        {
            "x": 2,
            "y": 1,
            "z": 1,
            "elements": "minecraft:lava@0"
        },
        {
            "x": -1,
            "y": -1,
            "z": 2,
            "elements": "modularmachinery:blockcasing@4"
        },
        {
            "x": 0,
            "y": -1,
            "z": 2,
            "elements": "modularmachinery:blockcasing@0"
        },
        {
            "x": 1,
            "y": 1,
            "z": 3,
            "elements": "appliedenergistics2:smooth_sky_stone_block@0"
        },
        {
            "x": 3,
            "y": 1,
            "z": 1,
            "elements": "minecraft:lava@0"
        },
        {
            "x": 2,
            "y": 1,
            "z": 3,
            "elements": "modularmachinery:blockcasing@3"
        },
        {
            "x": 1,
            "y": -1,
            "z": 2,
            "elements": "modularmachinery:blockcasing@0"
        },
        {
            "x": 4,
            "y": 1,
            "z": 1,
            "elements": "modularmachinery:blockcasing@3"
        },
        {
            "x": 3,
            "y": 1,
            "z": 3,
            "elements": "modularmachinery:blockcasing@3"
        },
        {
            "x": 2,
            "y": -1,
            "z": 2,
            "elements": "modularmachinery:blockcasing@0"
        },
        {
            "x": 4,
            "y": 1,
            "z": 3,
            "elements": "appliedenergistics2:smooth_sky_stone_block@0"
        },
        {
            "x": 3,
            "y": -1,
            "z": 2,
            "elements": "modularmachinery:blockcasing@0"
        },
        {
            "x": 4,
            "y": -1,
            "z": 2,
            "elements": "modularmachinery:blockcasing@4"
        }
    ]}